<?xml version="1.0" encoding="utf-8"?>
<!-- This URDF was automatically created by SolidWorks to URDF Exporter! Originally created by Stephen Brawner (brawner@gmail.com) 
     Commit Version: 1.6.0-1-g15f4949  Build Version: 1.6.7594.29634
     For more information, please see http://wiki.ros.org/sw_urdf_exporter -->
<robot
  name="manipulator1u1">
  <link
    name="Ground_link">
    <inertial>
      <origin
        xyz="-4.01267902239155E-09 0.154833811975906 -0.0276505560462275"
        rpy="0 0 0" />
      <mass
        value="3.346369786031" />
      <inertia
        ixx="0.0343204547292878"
        ixy="-3.93519296888634E-10"
        ixz="-3.36781864182438E-10"
        iyy="0.020256341441351"
        iyz="0.00201022007836559"
        izz="0.0473690302726349" />
    </inertial>
    <visual>
      <origin
        xyz="0 0 0"
        rpy="0 0 0" />
      <geometry>
        <mesh
          filename="package://manipulator1u1/meshes/Ground_link.STL" />
      </geometry>
      <material
        name="">
        <color
          rgba="0.792156862745098 0.819607843137255 0.933333333333333 1" />
      </material>
    </visual>
    <collision>
      <origin
        xyz="0 0 0"
        rpy="0 0 0" />
      <geometry>
        <mesh
          filename="package://manipulator1u1/meshes/Ground_link.STL" />
      </geometry>
    </collision>
  </link>
  <link
    name="Base_Link">
    <inertial>
      <origin
        xyz="-0.0018409 -3.8802E-05 0.081299"
        rpy="0 0 0" />
      <mass
        value="0.58835" />
      <inertia
        ixx="0.0018017"
        ixy="-8.0801E-06"
        ixz="5.5497E-05"
        iyy="0.0021849"
        iyz="1.1697E-06"
        izz="0.0011149" />
    </inertial>
    <visual>
      <origin
        xyz="0 0 0"
        rpy="0 0 0" />
      <geometry>
        <mesh
          filename="package://manipulator1u1/meshes/Base_Link.STL" />
      </geometry>
      <material
        name="">
        <color
          rgba="0.79216 0.81961 0.93333 1" />
      </material>
    </visual>
    <collision>
      <origin
        xyz="0 0 0"
        rpy="0 0 0" />
      <geometry>
        <mesh
          filename="package://manipulator1u1/meshes/Base_Link.STL" />
      </geometry>
    </collision>
  </link>
  <joint
    name="J_1"
    type="continuous">
    <origin
      xyz="0 0 0.05"
      rpy="0 0 0" />
    <parent
      link="Ground_link" />
    <child
      link="Base_Link" />
    <axis
      xyz="0 0 -1" />
  </joint>
  <link
    name="Shoulder_Link">
    <inertial>
      <origin
        xyz="0.143 0.0040737 0.07225"
        rpy="0 0 0" />
      <mass
        value="0.98156" />
      <inertia
        ixx="0.0027721"
        ixy="-3.4407E-05"
        ixz="5.6661E-05"
        iyy="0.0069733"
        iyz="4.6401E-07"
        izz="0.0059999" />
    </inertial>
    <visual>
      <origin
        xyz="0 0 0"
        rpy="0 0 0" />
      <geometry>
        <mesh
          filename="package://manipulator1u1/meshes/Shoulder_Link.STL" />
      </geometry>
      <material
        name="">
        <color
          rgba="0.79216 0.81961 0.93333 1" />
      </material>
    </visual>
    <collision>
      <origin
        xyz="0 0 0"
        rpy="0 0 0" />
      <geometry>
        <mesh
          filename="package://manipulator1u1/meshes/Shoulder_Link.STL" />
      </geometry>
    </collision>
  </link>
  <joint
    name="J_2"
    type="continuous">
    <origin
      xyz="-0.037923 -0.0037026 0.12"
      rpy="3.1205 -1.5708 0" />
    <parent
      link="Base_Link" />
    <child
      link="Shoulder_Link" />
    <axis
      xyz="0 0.076177 -0.99709" />
  </joint>
  <link
    name="Elbow_Link">
    <inertial>
      <origin
        xyz="0.10965 0.014569 -0.024767"
        rpy="0 0 0" />
      <mass
        value="0.50446" />
      <inertia
        ixx="0.00062795"
        ixy="-3.2869E-05"
        ixz="1.3073E-05"
        iyy="0.0024416"
        iyz="2.4843E-07"
        izz="0.0023224" />
    </inertial>
    <visual>
      <origin
        xyz="0 0 0"
        rpy="0 0 0" />
      <geometry>
        <mesh
          filename="package://manipulator1u1/meshes/Elbow_Link.STL" />
      </geometry>
      <material
        name="">
        <color
          rgba="0.79216 0.81961 0.93333 1" />
      </material>
    </visual>
    <collision>
      <origin
        xyz="0 0 0"
        rpy="0 0 0" />
      <geometry>
        <mesh
          filename="package://manipulator1u1/meshes/Elbow_Link.STL" />
      </geometry>
    </collision>
  </link>
  <joint
    name="J_3"
    type="continuous">
    <origin
      xyz="0.24993 -0.0060648 -0.00046334"
      rpy="0 0 0.008189" />
    <parent
      link="Shoulder_Link" />
    <child
      link="Elbow_Link" />
    <axis
      xyz="0 0 1" />
  </joint>
</robot>