<?xml version="1.0" encoding="utf-8"?>
<!-- This URDF was automatically created by SolidWorks to URDF Exporter! Originally created by Stephen Brawner (brawner@gmail.com) 
     Commit Version: 1.6.0-1-g15f4949  Build Version: 1.6.7594.29634
     For more information, please see http://wiki.ros.org/sw_urdf_exporter -->
<robot
  name="manipulator_m3_v2">
  <link
    name="Ground_link">
    <inertial>
      <origin
        xyz="-4.0127E-09 0.15483 0.057349"
        rpy="0 0 0" />
      <mass
        value="3.3464" />
      <inertia
        ixx="0.03432"
        ixy="-3.9352E-10"
        ixz="-3.3678E-10"
        iyy="0.020256"
        iyz="0.0020102"
        izz="0.047369" />
    </inertial>
    <visual>
      <origin
        xyz="0 0 0"
        rpy="0 0 0" />
      <geometry>
        <mesh
          filename="package://manipulator_m3_v2/meshes/Ground_link.STL" />
      </geometry>
      <material
        name="">
        <color
          rgba="0.75294 0.75294 0.75294 1" />
      </material>
    </visual>
    <collision>
      <origin
        xyz="0 0 0"
        rpy="0 0 0" />
      <geometry>
        <mesh
          filename="package://manipulator_m3_v2/meshes/Ground_link.STL" />
      </geometry>
    </collision>
  </link>
  <link
    name="Base_Link">
    <inertial>
      <origin
        xyz="-0.0018252 0.000243 0.081299"
        rpy="0 0 0" />
      <mass
        value="0.58835" />
      <inertia
        ixx="0.0018082"
        ixy="5.0169E-05"
        ixz="5.5023E-05"
        iyy="0.0021784"
        iyz="-7.3253E-06"
        izz="0.0011149" />
    </inertial>
    <visual>
      <origin
        xyz="0 0 0"
        rpy="0 0 0" />
      <geometry>
        <mesh
          filename="package://manipulator_m3_v2/meshes/Base_Link.STL" />
      </geometry>
      <material
        name="">
        <color
          rgba="0.79216 0.81961 0.93333 1" />
      </material>
    </visual>
    <collision>
      <origin
        xyz="0 0 0"
        rpy="0 0 0" />
      <geometry>
        <mesh
          filename="package://manipulator_m3_v2/meshes/Base_Link.STL" />
      </geometry>
    </collision>
  </link>
  <joint
    name="J_1"
    type="continuous">
    <origin
      xyz="0 0 0.135"
      rpy="0 0 0" />
    <parent
      link="Ground_link" />
    <child
      link="Base_Link" />
    <axis
      xyz="0 0 -1" />
    <limit
      lower="0"
      upper="0"
      effort="0"
      velocity="0" />
  </joint>
  <link
    name="Shoulder_Link">
    <inertial>
      <origin
        xyz="0.0025565 -0.086522 0.11272"
        rpy="0 0 0" />
      <mass
        value="0.98781" />
      <inertia
        ixx="0.0060003"
        ixy="3.4501E-05"
        ixz="-4.4949E-05"
        iyy="0.0054162"
        iyz="0.0020295"
        izz="0.0043299" />
    </inertial>
    <visual>
      <origin
        xyz="0 0 0"
        rpy="0 0 0" />
      <geometry>
        <mesh
          filename="package://manipulator_m3_v2/meshes/Shoulder_Link.STL" />
      </geometry>
      <material
        name="">
        <color
          rgba="0.79216 0.81961 0.93333 1" />
      </material>
    </visual>
    <collision>
      <origin
        xyz="0 0 0"
        rpy="0 0 0" />
      <geometry>
        <mesh
          filename="package://manipulator_m3_v2/meshes/Shoulder_Link.STL" />
      </geometry>
    </collision>
  </link>
  <joint
    name="J_2"
    type="continuous">
    <origin
      xyz="0 0 0.12"
      rpy="0 0 -0.13235" />
    <parent
      link="Base_Link" />
    <child
      link="Shoulder_Link" />
    <axis
      xyz="0.99986 0.017021 0" />
    <limit
      lower="0"
      upper="0"
      effort="0"
      velocity="0" />
  </joint>
  <link
    name="Elbow_Link">
    <inertial>
      <origin
        xyz="-0.00049847 -0.084051 0.088254"
        rpy="0 0 0" />
      <mass
        value="0.43553" />
      <inertia
        ixx="0.0023528"
        ixy="-1.1585E-06"
        ixz="1.1151E-06"
        iyy="0.0023426"
        iyz="0.0010074"
        izz="0.0024197" />
    </inertial>
    <visual>
      <origin
        xyz="0 0 0"
        rpy="0 0 0" />
      <geometry>
        <mesh
          filename="package://manipulator_m3_v2/meshes/Elbow_Link.STL" />
      </geometry>
      <material
        name="">
        <color
          rgba="0.79216 0.81961 0.93333 1" />
      </material>
    </visual>
    <collision>
      <origin
        xyz="0 0 0"
        rpy="0 0 0" />
      <geometry>
        <mesh
          filename="package://manipulator_m3_v2/meshes/Elbow_Link.STL" />
      </geometry>
    </collision>
  </link>
  <joint
    name="J_3"
    type="continuous">
    <origin
      xyz="0.0026628 -0.15642 0.195"
      rpy="0 0 0" />
    <parent
      link="Shoulder_Link" />
    <child
      link="Elbow_Link" />
    <axis
      xyz="0.99986 0.017021 0" />
    <limit
      lower="0"
      upper="0"
      effort="0"
      velocity="0" />
  </joint>
</robot>