<?xml version="1.0" encoding="utf-8"?>
<!-- This URDF was automatically created by SolidWorks to URDF Exporter! Originally created by Stephen Brawner (brawner@gmail.com) 
     Commit Version: 1.6.0-1-g15f4949  Build Version: 1.6.7594.29634
     For more information, please see http://wiki.ros.org/sw_urdf_exporter -->
<robot
  name="Manipulator2_URDF1">
  <link
    name="Ground_link">
    <inertial>
      <origin
        xyz="0.15942 0.00022321 0.056553"
        rpy="0 0 0" />
      <mass
        value="3.2586" />
      <inertia
        ixx="0.020199"
        ixy="-1.9577E-12"
        ixz="0.002049"
        iyy="0.034263"
        iyz="-1.7026E-07"
        izz="0.047317" />
    </inertial>
    <visual>
      <origin
        xyz="0 0 0"
        rpy="0 0 0" />
      <geometry>
        <mesh
          filename="package://Manipulator2_URDF1/meshes/Ground_link.STL" />
      </geometry>
      <material
        name="">
        <color
          rgba="0.79216 0.81961 0.93333 1" />
      </material>
    </visual>
    <collision>
      <origin
        xyz="0 0 0"
        rpy="0 0 0" />
      <geometry>
        <mesh
          filename="package://Manipulator2_URDF1/meshes/Ground_link.STL" />
      </geometry>
    </collision>
  </link>
  <link
    name="Base_Link">
    <inertial>
      <origin
        xyz="-0.0052112 -0.035227 -0.041033"
        rpy="0 0 0" />
      <mass
        value="0.88251" />
      <inertia
        ixx="0.0061551"
        ixy="-5.346E-12"
        ixz="0.00029044"
        iyy="0.0028459"
        iyz="-5.6663E-05"
        izz="0.005462" />
    </inertial>
    <visual>
      <origin
        xyz="0 0 0"
        rpy="0 0 0" />
      <geometry>
        <mesh
          filename="package://Manipulator2_URDF1/meshes/Base_Link.STL" />
      </geometry>
      <material
        name="">
        <color
          rgba="0.79216 0.81961 0.93333 1" />
      </material>
    </visual>
    <collision>
      <origin
        xyz="0 0 0"
        rpy="0 0 0" />
      <geometry>
        <mesh
          filename="package://Manipulator2_URDF1/meshes/Base_Link.STL" />
      </geometry>
    </collision>
  </link>
  <joint
    name="J_1"
    type="continuous">
    <origin
      xyz="0 0 0.2469"
      rpy="0 0 0.031005" />
    <parent
      link="Ground_link" />
    <child
      link="Base_Link" />
    <axis
      xyz="0 0 1" />
  </joint>
  <link
    name="Shoulder_Link">
    <inertial>
      <origin
        xyz="-0.0033732 -0.0035529 -0.0013357"
        rpy="0 0 0" />
      <mass
        value="0.79086" />
      <inertia
        ixx="0.003265"
        ixy="-0.0027194"
        ixz="7.6353E-05"
        iyy="0.0029202"
        iyz="8.434E-05"
        izz="0.0057241" />
    </inertial>
    <visual>
      <origin
        xyz="0 0 0"
        rpy="0 0 0" />
      <geometry>
        <mesh
          filename="package://Manipulator2_URDF1/meshes/Shoulder_Link.STL" />
      </geometry>
      <material
        name="">
        <color
          rgba="0.79216 0.81961 0.93333 1" />
      </material>
    </visual>
    <collision>
      <origin
        xyz="0 0 0"
        rpy="0 0 0" />
      <geometry>
        <mesh
          filename="package://Manipulator2_URDF1/meshes/Shoulder_Link.STL" />
      </geometry>
    </collision>
  </link>
  <joint
    name="J_2"
    type="continuous">
    <origin
      xyz="-0.085 0 0.028102"
      rpy="1.5708 0 -0.031005" />
    <parent
      link="Base_Link" />
    <child
      link="Shoulder_Link" />
    <axis
      xyz="-0.031 0 -0.99952" />
  </joint>
  <link
    name="Elbow_Link">
    <inertial>
      <origin
        xyz="0.061841 0.089272 -0.014547"
        rpy="0 0 0" />
      <mass
        value="0.58269" />
      <inertia
        ixx="0.003002"
        ixy="-0.0012758"
        ixz="-6.5052E-06"
        iyy="0.0031496"
        iyz="4.1321E-05"
        izz="0.0027328" />
    </inertial>
    <visual>
      <origin
        xyz="0 0 0"
        rpy="0 0 0" />
      <geometry>
        <mesh
          filename="package://Manipulator2_URDF1/meshes/Elbow_Link.STL" />
      </geometry>
      <material
        name="">
        <color
          rgba="0.79216 0.81961 0.93333 1" />
      </material>
    </visual>
    <collision>
      <origin
        xyz="0 0 0"
        rpy="0 0 0" />
      <geometry>
        <mesh
          filename="package://Manipulator2_URDF1/meshes/Elbow_Link.STL" />
      </geometry>
    </collision>
  </link>
  <joint
    name="J_3"
    type="continuous">
    <origin
      xyz="0.18653 0.16635 -0.0057853"
      rpy="0 0 0" />
    <parent
      link="Shoulder_Link" />
    <child
      link="Elbow_Link" />
    <axis
      xyz="-0.031 0 -0.99952" />
  </joint>
</robot>